Workbook

Sheet KPI Roll-Up
A1: OOI KPI Roll-Up
A3: Array | C3: Data Measure | D3: Q1 | E3: Q2 | F3: Q3 | G3: Q4 | I3: Array | J3: KPI | K3: Q1 | L3: Q2 | M3: Q3 | N3: Q4
A5: Pioneer | B5: Infrastructure Preparation | C5: Instrument Deployment Readiness | D5: ='Infrastructure Preparation'!D11 -> 1 | F5: ='Infrastructure Preparation'!E11 -> 1 | I5: Pioneer | J5: Infrastructure Preparation | K5: =AVERAGE(D5:D7) -> 1 | M5: =AVERAGE(F5:F7) -> 1
C6: Vehicle Deployment Readiness | D6: ='Infrastructure Preparation'!D15 -> NA | F6: ='Infrastructure Preparation'!E15 -> 1 | J6: Operations (Up Time) | K6: =AVERAGE(D9:D31) -> 0.9677795 | L6: =AVERAGE(E9:E31) -> 0.95690994 | M6: =AVERAGE(F9:F31) -> 0.98979592 | N6: =AVERAGE(G9:G31) -> 0
C7: Infrastructure Deployment Readiness | D7: ='Infrastructure Preparation'!D19 -> 1 | F7: ='Infrastructure Preparation'!E19 -> 1 | J7: Data Delivery | K7: =AVERAGE(D33:D50) -> 0.89063505 | L7: =AVERAGE(E33:E50) -> 0.74397746 | M7: =AVERAGE(F33:F50) -> 0.91291012 | N7: =AVERAGE(G33:G50) -> #DIV/0!
B9: Operations (Up Time) | C9: CNSM Operational Infrastructure Retention | D9: =Operations!BG10 -> 0.95652174 | E9: =Operations!BH10 -> 0.86956522 | F9: =Operations!BI10 -> 1 | G9: =Operations!BJ10 -> 0 | J9: Average KPI | K9: =AVERAGE(K5:K7) -> 0.95280485 | L9: =AVERAGE(L5:L7) -> 0.8504437 | M9: =AVERAGE(M5:M7) -> 0.96756868 | N9: =AVERAGE(N5:N7) -> #DIV/0!
C10: CNSM Platform Uptime | D10: =Operations!BG11 -> 1 | E10: =Operations!BH11 -> 1 | F10: =Operations!BI11 -> 1 | G10: =Operations!BJ11 -> 0
C12: CNSW Operational Infrastructure Retention | D12: =Operations!BG13 -> 1 | E12: =Operations!BH13 -> 1 | F12: =Operations!BI13 -> 1 | G12: =Operations!BJ13 -> 0 | I12: Regional Cabled Array | J12: Infrastructure Preparation | N12: =AVERAGE(G52:G53) -> #DIV/0!
C13: CNSW Platform Uptime | D13: =Operations!BG14 -> 1 | E13: =Operations!BH14 -> 1 | F13: =Operations!BI14 -> 1 | G13: =Operations!BJ14 -> 0 | J13: Operations (Up Time) | K13: =AVERAGE(D55:D56) -> 0 | L13: =AVERAGE(E55:E56) -> 0 | M13: =AVERAGE(F55:F56) -> 0 | N13: =AVERAGE(G55:G56) -> 0
J14: Data Delivery | K14: =AVERAGE(D76:D78) -> 0.94871795 | L14: =AVERAGE(E76:E78) -> 0.9525641 | M14: =AVERAGE(F76:F78) -> 0.94461538 | N14: =AVERAGE(G76:G78) -> 0
C15: NOPM Operational Infrastructure Retention | D15: =Operations!BG16 -> 0.78571429 | E15: =Operations!BH16 -> 0.78571429 | F15: =Operations!BI16 -> 0.92857143 | G15: =Operations!BJ16 -> 0
C16: NOPM Platform Uptime | D16: =Operations!BG17 -> 1 | E16: =Operations!BH17 -> 1 | F16: =Operations!BI17 -> 1 | G16: =Operations!BJ17 -> 0 | J16: Average KPI | K16: =AVERAGE(K12:K14) -> 0.47435897 | L16: =AVERAGE(L12:L14) -> 0.47628205 | M16: =AVERAGE(M12:M14) -> 0.47230769 | N16: =AVERAGE(N12:N14) -> #DIV/0!
C18: SOPM Operational Infrastructure Retention | D18: =Operations!BG19 -> 1 | E18: =Operations!BH19 -> 1 | F18: =Operations!BI19 -> 0.92857143 | G18: =Operations!BJ19 -> 0
C19: SOPM Platform Uptime | D19: =Operations!BG20 -> 1 | E19: =Operations!BH20 -> 1 | F19: =Operations!BI20 -> 1 | G19: =Operations!BJ20 -> 0
C21: CS Glider Operational Infrastructure Retention | D21: =Operations!BG22 -> NA | E21: =Operations!BH22 -> NA | F21: =Operations!BI22 -> 1 | G21: =Operations!BJ22 -> 0
C22: CS Glider Platform Uptime | D22: =Operations!BG23 -> NA | E22: =Operations!BH23 -> NA | F22: =Operations!BI23 -> 1 | G22: =Operations!BJ23 -> 0
C24: MA Glider Operational Infrastructure Retention | D24: =Operations!BG25 -> NA | E24: =Operations!BH25 -> NA | F24: =Operations!BI25 -> 1 | G24: =Operations!BJ25 -> 0
C25: MA Glider Platform Uptime | D25: =Operations!BG26 -> NA | E25: =Operations!BH26 -> NA | F25: =Operations!BI26 -> 1 | G25: =Operations!BJ26 -> 0
C27: OM Glider Operational Infrastructure Retention | D27: =Operations!BG28 -> NA | E27: =Operations!BH28 -> NA | F27: =Operations!BI28 -> 1 | G27: =Operations!BJ28 -> 0
C28: OM Glider Platform Uptime | D28: =Operations!BG29 -> NA | E28: =Operations!BH29 -> NA | F28: =Operations!BI29 -> 1 | G28: =Operations!BJ29 -> 0
C30: OF Glider Operational Infrastructure Retention | D30: =Operations!BG31 -> NA | E30: =Operations!BH31 -> NA | F30: =Operations!BI31 -> NA | G30: =Operations!BJ31 -> 0
C31: OF Glider Platform Uptime | D31: =Operations!BG32 -> NA | E31: =Operations!BH32 -> NA | F31: =Operations!BI32 -> NA | G31: =Operations!BJ32 -> 0
B33: Data Delivery | C33: CNSM Technical Data Availability | D33: ='Data Delivery'!DJ11 -> 1 | E33: ='Data Delivery'!DK11 -> 1 | F33: ='Data Delivery'!DL11 -> 1 | G33: ='Data Delivery'!DM11 -> #DIV/0!
C34: CNSM Science Data Availability | D34: ='Data Delivery'!DJ12 -> 1 | E34: ='Data Delivery'!DK12 -> 0.91987179 | F34: ='Data Delivery'!DL12 -> 0.93589744 | G34: ='Data Delivery'!DM12 -> 0
C35: CNSM Data Availability Retention | D35: ='Data Delivery'!DJ13 -> 0.93548387 | E35: ='Data Delivery'!DK13 -> 0.84119107 | F35: ='Data Delivery'!DL13 -> 0.89081886 | G35: ='Data Delivery'!DM13 -> #DIV/0!
C38: CNSW Technical Data Availability | D38: ='Data Delivery'!DJ16 -> 0.94871795 | E38: ='Data Delivery'!DK16 -> 0.66666667 | F38: ='Data Delivery'!DL16 -> 0.8974359 | G38: ='Data Delivery'!DM16 -> #DIV/0!
C39: CNSW Science Data Availability | D39: ='Data Delivery'!DJ17 -> 0.92307692 | E39: ='Data Delivery'!DK17 -> 0.5 | F39: ='Data Delivery'!DL17 -> 0.84615385 | G39: ='Data Delivery'!DM17 -> 0
C40: CNSW Data Availability Retention | D40: ='Data Delivery'!DJ18 -> 1 | E40: ='Data Delivery'!DK18 -> 1 | F40: ='Data Delivery'!DL18 -> 1 | G40: ='Data Delivery'!DM18 -> #DIV/0!
C43: NOPM Technical Data Availability | D43: ='Data Delivery'!DJ21 -> 0.46153846 | E43: ='Data Delivery'!DK21 -> 0 | F43: ='Data Delivery'!DL21 -> 0.69230769 | G43: ='Data Delivery'!DM21 -> #DIV/0!
C44: NOPM Science Data Availability | D44: ='Data Delivery'!DJ22 -> 0.46153846 | E44: ='Data Delivery'!DK22 -> 0 | F44: ='Data Delivery'!DL22 -> 0.69230769 | G44: ='Data Delivery'!DM22 -> 0
C45: NOPM Data Availability Retention | D45: ='Data Delivery'!DJ23 -> 0.95726496 | E45: ='Data Delivery'!DK23 -> 1 | F45: ='Data Delivery'!DL23 -> 1 | G45: ='Data Delivery'!DM23 -> #DIV/0!
C48: SOPM Technical Data Availability | D48: ='Data Delivery'!DJ26 -> 1 | E48: ='Data Delivery'!DK26 -> 1 | F48: ='Data Delivery'!DL26 -> 1 | G48: ='Data Delivery'!DM26 -> #DIV/0!
C49: SOPM Science Data Availability | D49: ='Data Delivery'!DJ27 -> 1 | E49: ='Data Delivery'!DK27 -> 1 | F49: ='Data Delivery'!DL27 -> 1 | G49: ='Data Delivery'!DM27 -> 0
C50: SOPM Data Availability Retention | D50: ='Data Delivery'!DJ28 -> 1 | E50: ='Data Delivery'!DK28 -> 1 | F50: ='Data Delivery'!DL28 -> 1 | G50: ='Data Delivery'!DM28 -> #DIV/0!
A52: Regional Cabled Array | B52: Infrastructure Preparation | C52: Instrument Deployment Readiness | G52: ='Infrastructure Preparation'!F24 -> NA
C53: Infrastructure Deployment Readiness | G53: ='Infrastructure Preparation'!F28 -> NA
B55: Operations | C55: PN01A - Slope Base Primary Node Instrument Retention | D55: =Operations!BG35 -> 0 | E55: =Operations!BH35 -> 0 | F55: =Operations!BI35 -> 0 | G55: =Operations!BJ35 -> 0
C56: PN01A - Slope Base Primary Node Platform Uptime | D56: =Operations!BG36 -> 0 | E56: =Operations!BH36 -> 0 | F56: =Operations!BI36 -> 0 | G56: =Operations!BJ36 -> 0
C58: PN01C - Endurance Offshore Primary Node (600m) Instrument Retention | D58: =Operations!BG38 -> 0 | E58: =Operations!BH38 -> 0 | F58: =Operations!BI38 -> 0 | G58: =Operations!BJ38 -> 0
C59: PN01C - Endurance Offshore Primary Node (600m) Platform Uptime | D59: =Operations!BG39 -> 0 | E59: =Operations!BH39 -> 0 | F59: =Operations!BI39 -> 0 | G59: =Operations!BJ39 -> 0
...

Sheet Infrastructure Preparation
A1: Infrastructure Preparation
C3: IRR | D3: Pioneer Fall | E3: Pioneer Spring | F3: RCA
C4: Quarter of IRR (Q1, Q2, Q3, Q4) | D4: Q1 | E4: Q3 | F4: Q4
B6: Array | C6: Data Measure
B8: Pioneer
C9: Baseline Instruments Planned | D9: 60 | E9: 60
C10: Instruments Ready To Deploy | D10: 60 | E10: 60
C11: Instrument Deployment Readiness | D11: =IF(D9=0,"NA",D10/D9) -> 1 | E11: =IF(E9=0,"NA",E10/E9) -> 1
C13: Baseline Vehicles Planned | D13: 0 | E13: 4
C14: Vehicles Ready To Deploy | D14: 0 | E14: 4
C15: Vehicle Deployment Readiness | D15: =IF(D13=0,"NA",D14/D13) -> NA | E15: =IF(E13=0,"NA",E14/E13) -> 1
C17: Infrastructure Planned | D17: 4 | E17: 4
C18: Infrastructure Ready To Deploy | D18: 4 | E18: 4
C19: Infrastructure Deployment Readiness | D19: =IF(D17=0,"NA",D18/D17) -> 1 | E19: =IF(E17=0,"NA",E18/E17) -> 1
B21: Regional Cabled Array
C22: Baseline Instruments Planned
C23: Instruments Ready To Deploy
C24: Instrument Deployment Readiness | F24: =IF(F22=0,"NA",F23/F22) -> NA
C26: Infrastructure Planned
C27: Infrastructure Ready
C28: Infrastructure Deployment Readiness | F28: =IF(F26=0,"NA",F27/F26) -> NA

Sheet Operations
A1: Operations
A3: Start | B3: 45931 | C3: Week of | D3: 45936 | E3: =D3+7 -> 45943 | F3: =E3+7 -> 45950 | G3: =F3+7 -> 45957 | H3: =G3+7 -> 45964 | I3: =H3+7 -> 45971 | J3: =I3+7 -> 45978 | K3: =J3+7 -> 45985 | L3: =K3+7 -> 45992 | ... BC3: =BB3+7 -> 46293 | BD3: 46295 | BG3: Q1 | BH3: Q2 | BI3: Q3 | BJ3: Q4
C4: Days | D4: =D3-B3+1 -> 6 | E4: =E3-D3 -> 7 | F4: =F3-E3 -> 7 | G4: =G3-F3 -> 7 | H4: =H3-G3 -> 7 | I4: =I3-H3 -> 7 | J4: =J3-I3 -> 7 | K4: =K3-J3 -> 7 | L4: =L3-K3 -> 7 | ... BD4: =BD3-BC3 -> 2
C5: Cumulative Days | D5: =D4 -> 6 | E5: =E4+D5 -> 13 | F5: =F4+E5 -> 20 | G5: =G4+F5 -> 27 | H5: =H4+G5 -> 34 | I5: =I4+H5 -> 41 | J5: =J4+I5 -> 48 | K5: =K4+J5 -> 55 | L5: =L4+K5 -> 62 | ... BD5: =BD4+BC5 -> 365
B7: Array | C7: Data Measure
B9: Pioneer
C10: CNSM Infrastructure Operation % | D10: 1 | E10: 1 | F10: 1 | G10: 1 | H10: 1 | I10: 1 | J10: 1 | K10: 0.95652174 | L10: 0.95652174 | M10: 0.95652174 | N10: 0.95652174 | O10: 0.95652174 | P10: 0.95652174 | Q10: 0.95652174 | R10: 0.95652174 | S10: 0.95652174 | T10: 0.95652174 | U10: 0.95652174 | V10: 0.95652174 | W10: 0.95652174 | X10: 0.95652174 | Y10: 0.86956522 | Z10: 0.86956522 | AA10: 0.86956522 | AB10: 0.86956522 | AC10: 0.86956522 | AD10: 0.86956522 | AE10: 0.86956522 | AF10: 0.86956522 | AG10: 0.86956522 | AH10: 1 | AI10: 1 | AJ10: 1 | AK10: 1 | AL10: 1 | AM10: 1 | AN10: 1 | AO10: 1 | AP10: 1 | BF10: CNSM Operational Infrastructure Retention | BG10: =P10 -> 0.95652174 | BH10: =AC10 -> 0.86956522 | BI10: =AP10 -> 1 | BJ10: =BD10 -> 0
C11: CNSM Platform Operational Days | D11: =IF(D10>=0.7,D$4,0) -> 6 | E11: =IF(E10>=0.7,E$4,0) -> 7 | F11: =IF(F10>=0.7,F$4,0) -> 7 | G11: =IF(G10>=0.7,G$4,0) -> 7 | H11: =IF(H10>=0.7,H$4,0) -> 7 | I11: =IF(I10>=0.7,I$4,0) -> 7 | J11: =IF(J10>=0.7,J$4,0) -> 7 | K11: =IF(K10>=0.7,K$4,0) -> 7 | ... BD11: =IF(BD10>=0.7,BD$4,0) -> 0 | BF11: CNSM Platform Uptime | BG11: =IF(BG10="NA","NA",SUM(D11:P11)/SUM($D$4:$P$4)) -> 1 | BH11: =IF(BH10="NA","NA",SUM(R11:AC11)/SUM($R$4:$AC$4)) -> 1 | BI11: =IF(BI10="NA","NA",SUM(AD11:AP11)/SUM($AD$4:$AP$4)) -> 1 | BJ11: =IF(BJ10="NA","NA",SUM(AQ11:BD11)/SUM($AQ$4:$BD$4)) -> 0
C13: CNSW Infrastructure Operation % | D13: 1 | E13: 1 | F13: 1 | G13: 1 | H13: 1 | I13: 1 | J13: 0.85714286 | K13: 1 | L13: 1 | M13: 1 | N13: 1 | O13: 1 | P13: 1 | Q13: 1 | R13: 1 | S13: 1 | T13: 1 | U13: 1 | V13: 1 | W13: 1 | X13: 1 | Y13: 1 | Z13: 1 | AA13: 1 | AB13: 1 | AC13: 1 | AD13: 1 | AE13: 1 | AF13: 1 | AG13: 1 | AH13: 1 | AI13: 1 | AJ13: 1 | AK13: 1 | AL13: 1 | AM13: 1 | AN13: 1 | AO13: 1 | AP13: 1 | BF13: CNSW Operational Infrastructure Retention | BG13: =P13 -> 1 | BH13: =AC13 -> 1 | BI13: =AP13 -> 1 | BJ13: =BD13 -> 0
C14: CNSW Platform Operational Days | D14: =IF(D13>=0.7,D$4,0) -> 6 | E14: =IF(E13>=0.7,E$4,0) -> 7 | F14: =IF(F13>=0.7,F$4,0) -> 7 | G14: =IF(G13>=0.7,G$4,0) -> 7 | H14: =IF(H13>=0.7,H$4,0) -> 7 | I14: =IF(I13>=0.7,I$4,0) -> 7 | J14: =IF(J13>=0.7,J$4,0) -> 7 | K14: =IF(K13>=0.7,K$4,0) -> 7 | ... BD14: =IF(BD13>=0.7,BD$4,0) -> 0 | BF14: CNSW Platform Uptime | BG14: =IF(BG13="NA","NA",SUM(D14:P14)/SUM($D$4:$P$4)) -> 1 | BH14: =IF(BH13="NA","NA",SUM(R14:AC14)/SUM($R$4:$AC$4)) -> 1 | BI14: =IF(BI13="NA","NA",SUM(AD14:AP14)/SUM($AD$4:$AP$4)) -> 1 | BJ14: =IF(BJ13="NA","NA",SUM(AQ14:BD14)/SUM($AQ$4:$BD$4)) -> 0
C16: NOPM Infrastructure Operation % | D16: 1 | E16: 1 | F16: 1 | G16: 1 | H16: 1 | I16: 1 | J16: 0.78571429 | K16: 0.78571429 | L16: 0.78571429 | M16: 0.78571429 | N16: 0.78571429 | O16: 0.78571429 | P16: 0.78571429 | Q16: 0.78571429 | R16: 0.78571429 | S16: 0.78571429 | T16: 0.78571429 | U16: 0.78571429 | V16: 0.78571429 | W16: 0.78571429 | X16: 0.78571429 | Y16: 0.78571429 | Z16: 0.78571429 | AA16: 0.78571429 | AB16: 0.78571429 | AC16: 0.78571429 | AD16: 0.78571429 | AE16: 0.78571429 | AF16: 0.78571429 | AG16: 0.78571429 | AH16: 1 | AI16: 1 | AJ16: 1 | AK16: 1 | AL16: 1 | AM16: 1 | AN16: 1 | AO16: 0.92857143 | AP16: 0.92857143 | BF16: NOPM Operational Infrastructure Retention | BG16: =P16 -> 0.78571429 | BH16: =AC16 -> 0.78571429 | BI16: =AP16 -> 0.92857143 | BJ16: =BD16 -> 0
C17: NOPM Platform Operational Days | D17: =IF(D16>=0.7,D$4,0) -> 6 | E17: =IF(E16>=0.7,E$4,0) -> 7 | F17: =IF(F16>=0.7,F$4,0) -> 7 | G17: =IF(G16>=0.7,G$4,0) -> 7 | H17: =IF(H16>=0.7,H$4,0) -> 7 | I17: =IF(I16>=0.7,I$4,0) -> 7 | J17: =IF(J16>=0.7,J$4,0) -> 7 | K17: =IF(K16>=0.7,K$4,0) -> 7 | ... BD17: =IF(BD16>=0.7,BD$4,0) -> 0 | BF17: NOPM Platform Uptime | BG17: =IF(BG16="NA","NA",SUM(D17:P17)/SUM($D$4:$P$4)) -> 1 | BH17: =IF(BH16="NA","NA",SUM(R17:AC17)/SUM($R$4:$AC$4)) -> 1 | BI17: =IF(BI16="NA","NA",SUM(AD17:AP17)/SUM($AD$4:$AP$4)) -> 1 | BJ17: =IF(BJ16="NA","NA",SUM(AQ17:BD17)/SUM($AQ$4:$BD$4)) -> 0
C19: SOPM Infrastructure Operation % | D19: 1 | E19: 1 | F19: 1 | G19: 1 | H19: 1 | I19: 1 | J19: 1 | K19: 1 | L19: 1 | M19: 1 | N19: 1 | O19: 1 | P19: 1 | Q19: 1 | R19: 1 | S19: 1 | T19: 1 | U19: 1 | V19: 1 | W19: 1 | X19: 1 | Y19: 1 | Z19: 1 | AA19: 1 | AB19: 1 | AC19: 1 | AD19: 1 | AE19: 1 | AF19: 1 | AG19: 1 | AH19: 1 | AI19: 1 | AJ19: 1 | AK19: 1 | AL19: 0.92857143 | AM19: 0.92857143 | AN19: 0.92857143 | AO19: 0.92857143 | AP19: 0.92857143 | BF19: SOPM Operational Infrastructure Retention | BG19: =P19 -> 1 | BH19: =AC19 -> 1 | BI19: =AP19 -> 0.92857143 | BJ19: =BD19 -> 0
C20: SOPM Platform Operational Days | D20: =IF(D19>=0.7,D$4,0) -> 6 | E20: =IF(E19>=0.7,E$4,0) -> 7 | F20: =IF(F19>=0.7,F$4,0) -> 7 | G20: =IF(G19>=0.7,G$4,0) -> 7 | H20: =IF(H19>=0.7,H$4,0) -> 7 | I20: =IF(I19>=0.7,I$4,0) -> 7 | J20: =IF(J19>=0.7,J$4,0) -> 7 | K20: =IF(K19>=0.7,K$4,0) -> 7 | ... BD20: =IF(BD19>=0.7,BD$4,0) -> 0 | BF20: SOPM Platform Uptime | BG20: =IF(BG19="NA","NA",SUM(D20:P20)/SUM($D$4:$P$4)) -> 1 | BH20: =IF(BH19="NA","NA",SUM(R20:AC20)/SUM($R$4:$AC$4)) -> 1 | BI20: =IF(BI19="NA","NA",SUM(AD20:AP20)/SUM($AD$4:$AP$4)) -> 1 | BJ20: =IF(BJ19="NA","NA",SUM(AQ20:BD20)/SUM($AQ$4:$BD$4)) -> 0
C22: CS Glider Infrastructure Operation % | D22: NA | E22: NA | F22: NA | G22: NA | H22: NA | I22: NA | J22: NA | K22: NA | L22: NA | M22: NA | N22: NA | O22: NA | P22: NA | Q22: NA | R22: NA | S22: NA | T22: NA | U22: NA | V22: NA | W22: NA | X22: NA | Y22: NA | Z22: NA | AA22: NA | AB22: NA | AC22: NA | AD22: NA | AE22: NA | AF22: NA | AG22: NA | AH22: 1 | AI22: 1 | AJ22: 1 | AK22: 1 | AL22: 1 | AM22: 1 | AN22: 1 | AO22: 1 | AP22: 1 | BF22: CS Glider Operational Infrastructure Retention | BG22: =P22 -> NA | BH22: =AC22 -> NA | BI22: =AP22 -> 1 | BJ22: =BD22 -> 0
C23: CS Glider Operational Days | D23: =IF(D22>=0.7,D$4,0) -> 6 | E23: =IF(E22>=0.7,E$4,0) -> 7 | F23: =IF(F22>=0.7,F$4,0) -> 7 | G23: =IF(G22>=0.7,G$4,0) -> 7 | H23: =IF(H22>=0.7,H$4,0) -> 7 | I23: =IF(I22>=0.7,I$4,0) -> 7 | J23: =IF(J22>=0.7,J$4,0) -> 7 | K23: =IF(K22>=0.7,K$4,0) -> 7 | ... BD23: =IF(BD22>=0.7,BD$4,0) -> 0 | BF23: CS Glider Platform Uptime | BG23: =IF(BG22="NA","NA",SUM(D23:P23)/SUM($D$4:$P$4)) -> NA | BH23: =IF(BH22="NA","NA",SUM(R23:AC23)/SUM($R$4:$AC$4)) -> NA | BI23: =IF(BI22="NA","NA",SUM(AD23:AP23)/SUM($AD$4:$AP$4)) -> 1 | BJ23: =IF(BJ22="NA","NA",SUM(AQ23:BD23)/SUM($AQ$4:$BD$4)) -> 0
C25: MA Glider Infrastructure Operation % | D25: NA | E25: NA | F25: NA | G25: NA | H25: NA | I25: NA | J25: NA | K25: NA | L25: NA | M25: NA | N25: NA | O25: NA | P25: NA | Q25: NA | R25: NA | S25: NA | T25: NA | U25: NA | V25: NA | W25: NA | X25: NA | Y25: NA | Z25: NA | AA25: NA | AB25: NA | AC25: NA | AD25: NA | AE25: NA | AF25: NA | AG25: NA | AH25: 1 | AI25: 1 | AJ25: 1 | AK25: 1 | AL25: 1 | AM25: 1 | AN25: 1 | AO25: 1 | AP25: 1 | BF25: MA Glider Operational Infrastructure Retention | BG25: =P25 -> NA | BH25: =AC25 -> NA | BI25: =AP25 -> 1 | BJ25: =BD25 -> 0
C26: MA Glider Platform Operational Days | D26: =IF(D25>=0.7,D$4,0) -> 6 | E26: =IF(E25>=0.7,E$4,0) -> 7 | F26: =IF(F25>=0.7,F$4,0) -> 7 | G26: =IF(G25>=0.7,G$4,0) -> 7 | H26: =IF(H25>=0.7,H$4,0) -> 7 | I26: =IF(I25>=0.7,I$4,0) -> 7 | J26: =IF(J25>=0.7,J$4,0) -> 7 | K26: =IF(K25>=0.7,K$4,0) -> 7 | ... BD26: =IF(BD25>=0.7,BD$4,0) -> 0 | BF26: MA Glider Platform Uptime | BG26: =IF(BG25="NA","NA",SUM(D26:P26)/SUM($D$4:$P$4)) -> NA | BH26: =IF(BH25="NA","NA",SUM(R26:AC26)/SUM($R$4:$AC$4)) -> NA | BI26: =IF(BI25="NA","NA",SUM(AD26:AP26)/SUM($AD$4:$AP$4)) -> 1 | BJ26: =IF(BJ25="NA","NA",SUM(AQ26:BD26)/SUM($AQ$4:$BD$4)) -> 0
C28: OM Glider Infrastructure Operation % | D28: NA | E28: NA | F28: NA | G28: NA | H28: NA | I28: NA | J28: NA | K28: NA | L28: NA | M28: NA | N28: NA | O28: NA | P28: NA | Q28: NA | R28: NA | S28: NA | T28: NA | U28: NA | V28: NA | W28: NA | X28: NA | Y28: NA | Z28: NA | AA28: NA | AB28: NA | AC28: NA | AD28: NA | AE28: NA | AF28: NA | AG28: NA | AH28: 1 | AI28: 1 | AJ28: 1 | AK28: 1 | AL28: 1 | AM28: 1 | AN28: 1 | AO28: 1 | AP28: 1 | BF28: OM Glider Operational Infrastructure Retention | BG28: =P28 -> NA | BH28: =AC28 -> NA | BI28: =AP28 -> 1 | BJ28: =BD28 -> 0
C29: OM Glider Platform Operational Days | D29: =IF(D28>=0.7,D$4,0) -> 6 | E29: =IF(E28>=0.7,E$4,0) -> 7 | F29: =IF(F28>=0.7,F$4,0) -> 7 | G29: =IF(G28>=0.7,G$4,0) -> 7 | H29: =IF(H28>=0.7,H$4,0) -> 7 | I29: =IF(I28>=0.7,I$4,0) -> 7 | J29: =IF(J28>=0.7,J$4,0) -> 7 | K29: =IF(K28>=0.7,K$4,0) -> 7 | ... BD29: =IF(BD28>=0.7,BD$4,0) -> 0 | BF29: OM Glider Platform Uptime | BG29: =IF(BG28="NA","NA",SUM(D29:P29)/SUM($D$4:$P$4)) -> NA | BH29: =IF(BH28="NA","NA",SUM(R29:AC29)/SUM($R$4:$AC$4)) -> NA | BI29: =IF(BI28="NA","NA",SUM(AD29:AP29)/SUM($AD$4:$AP$4)) -> 1 | BJ29: =IF(BJ28="NA","NA",SUM(AQ29:BD29)/SUM($AQ$4:$BD$4)) -> 0
C31: OF Glider Infrastructure Operation % | D31: NA | E31: NA | F31: NA | G31: NA | H31: NA | I31: NA | J31: NA | K31: NA | L31: NA | M31: NA | N31: NA | O31: NA | P31: NA | Q31: NA | R31: NA | S31: NA | T31: NA | U31: NA | V31: NA | W31: NA | X31: NA | Y31: NA | Z31: NA | AA31: NA | AB31: NA | AC31: NA | AD31: NA | AE31: NA | AF31: NA | AG31: NA | AH31: 1 | AI31: 1 | AJ31: NA | AK31: NA | AL31: NA | AM31: NA | AN31: NA | AO31: NA | AP31: NA | BF31: OF Glider Operational Infrastructure Retention | BG31: =P31 -> NA | BH31: =AC31 -> NA | BI31: =AP31 -> NA | BJ31: =BD31 -> 0
C32: OF Glider Platform Operational Days | D32: =IF(D31>=0.7,D$4,0) -> 6 | E32: =IF(E31>=0.7,E$4,0) -> 7 | F32: =IF(F31>=0.7,F$4,0) -> 7 | G32: =IF(G31>=0.7,G$4,0) -> 7 | H32: =IF(H31>=0.7,H$4,0) -> 7 | I32: =IF(I31>=0.7,I$4,0) -> 7 | J32: =IF(J31>=0.7,J$4,0) -> 7 | K32: =IF(K31>=0.7,K$4,0) -> 7 | ... BD32: =IF(BD31>=0.7,BD$4,0) -> 0 | BF32: OF Glider Platform Uptime | BG32: =IF(BG31="NA","NA",SUM(D32:P32)/SUM($D$4:$P$4)) -> NA | BH32: =IF(BH31="NA","NA",SUM(R32:AC32)/SUM($R$4:$AC$4)) -> NA | BI32: =IF(BI31="NA","NA",SUM(AD32:AP32)/SUM($AD$4:$AP$4)) -> NA | BJ32: =IF(BJ31="NA","NA",SUM(AQ32:BD32)/SUM($AQ$4:$BD$4)) -> 0
B34: Regional Cabled Array
C35: PN01A - Slope Base Primary Node Operation % | BF35: PN01A - Slope Base Primary Node Instrument Retention | BG35: =P35 -> 0 | BH35: =AC35 -> 0 | BI35: =AP35 -> 0 | BJ35: =BD35 -> 0
C36: PN01A - Slope Base Primary Node Operational Days | D36: =IF(D35>=0.7,D$4,0) -> 0 | E36: =IF(E35>=0.7,E$4,0) -> 0 | F36: =IF(F35>=0.7,F$4,0) -> 0 | G36: =IF(G35>=0.7,G$4,0) -> 0 | H36: =IF(H35>=0.7,H$4,0) -> 0 | I36: =IF(I35>=0.7,I$4,0) -> 0 | J36: =IF(J35>=0.7,J$4,0) -> 0 | K36: =IF(K35>=0.7,K$4,0) -> 0 | ... BD36: =IF(BD35>=0.7,BD$4,0) -> 0 | BF36: PN01A - Slope Base Primary Node Platform Uptime | BG36: =IF(BG35="NA","NA",SUM(D36:P36)/SUM($D$4:$P$4)) -> 0 | BH36: =IF(BH35="NA","NA",SUM(R36:AC36)/SUM($R$4:$AC$4)) -> 0 | BI36: =IF(BI35="NA","NA",SUM(AD36:AP36)/SUM($AD$4:$AP$4)) -> 0 | BJ36: =IF(BJ35="NA","NA",SUM(AQ36:BD36)/SUM($AQ$4:$BD$4)) -> 0
C38: PN01C - Endurance Offshore Primary Node (600m) Operation % | BF38: PN01C - Endurance Offshore Primary Node (600m) Instrument Retention | BG38: =P38 -> 0 | BH38: =AC38 -> 0 | BI38: =AP38 -> 0 | BJ38: =BD38 -> 0
C39: PN01C - Endurance Offshore Primary Node (600m) Operational Days | D39: =IF(D38>=0.7,D$4,0) -> 0 | E39: =IF(E38>=0.7,E$4,0) -> 0 | F39: =IF(F38>=0.7,F$4,0) -> 0 | G39: =IF(G38>=0.7,G$4,0) -> 0 | H39: =IF(H38>=0.7,H$4,0) -> 0 | I39: =IF(I38>=0.7,I$4,0) -> 0 | J39: =IF(J38>=0.7,J$4,0) -> 0 | K39: =IF(K38>=0.7,K$4,0) -> 0 | ... BD39: =IF(BD38>=0.7,BD$4,0) -> 0 | BF39: PN01C - Endurance Offshore Primary Node (600m) Platform Uptime | BG39: =IF(BG38="NA","NA",SUM(D39:P39)/SUM($D$4:$P$4)) -> 0 | BH39: =IF(BH38="NA","NA",SUM(R39:AC39)/SUM($R$4:$AC$4)) -> 0 | BI39: =IF(BI38="NA","NA",SUM(AD39:AP39)/SUM($AD$4:$AP$4)) -> 0 | BJ39: =IF(BJ38="NA","NA",SUM(AQ39:BD39)/SUM($AQ$4:$BD$4)) -> 0
C41: PN01D - Endurance Shelf Primary Node Operation % | BF41: PN01D - Endurance Shelf Primary Node Instrument Retention | BG41: =P41 -> 0 | BH41: =AC41 -> 0 | BI41: =AP41 -> 0 | BJ41: =BD41 -> 0
C42: PN01D - Endurance Shelf Primary Node Operational Days | D42: =IF(D41>=0.7,D$4,0) -> 0 | E42: =IF(E41>=0.7,E$4,0) -> 0 | F42: =IF(F41>=0.7,F$4,0) -> 0 | G42: =IF(G41>=0.7,G$4,0) -> 0 | H42: =IF(H41>=0.7,H$4,0) -> 0 | I42: =IF(I41>=0.7,I$4,0) -> 0 | J42: =IF(J41>=0.7,J$4,0) -> 0 | K42: =IF(K41>=0.7,K$4,0) -> 0 | ... BD42: =IF(BD41>=0.7,BD$4,0) -> 0 | BF42: PN01D - Endurance Shelf Primary Node Platform Uptime | BG42: =IF(BG41="NA","NA",SUM(D42:P42)/SUM($D$4:$P$4)) -> 0 | BH42: =IF(BH41="NA","NA",SUM(R42:AC42)/SUM($R$4:$AC$4)) -> 0 | BI42: =IF(BI41="NA","NA",SUM(AD42:AP42)/SUM($AD$4:$AP$4)) -> 0 | BJ42: =IF(BJ41="NA","NA",SUM(AQ42:BD42)/SUM($AQ$4:$BD$4)) -> 0
C44: PN03A - Axial Base Primary Node Operation % | BF44: PN03A - Axial Base Primary Node Instrument Retention | BG44: =P44 -> 0 | BH44: =AC44 -> 0 | BI44: =AP44 -> 0 | BJ44: =BD44 -> 0
C45: PN03A - Axial Base Primary Node Operational Days | D45: =IF(D44>=0.7,D$4,0) -> 0 | E45: =IF(E44>=0.7,E$4,0) -> 0 | F45: =IF(F44>=0.7,F$4,0) -> 0 | G45: =IF(G44>=0.7,G$4,0) -> 0 | H45: =IF(H44>=0.7,H$4,0) -> 0 | I45: =IF(I44>=0.7,I$4,0) -> 0 | J45: =IF(J44>=0.7,J$4,0) -> 0 | K45: =IF(K44>=0.7,K$4,0) -> 0 | ... BD45: =IF(BD44>=0.7,BD$4,0) -> 0 | BF45: PN03A - Axial Base Primary Node Platform Uptime | BG45: =IF(BG44="NA","NA",SUM(D45:P45)/SUM($D$4:$P$4)) -> 0 | BH45: =IF(BH44="NA","NA",SUM(R45:AC45)/SUM($R$4:$AC$4)) -> 0 | BI45: =IF(BI44="NA","NA",SUM(AD45:AP45)/SUM($AD$4:$AP$4)) -> 0 | BJ45: =IF(BJ44="NA","NA",SUM(AQ45:BD45)/SUM($AQ$4:$BD$4)) -> 0
C47: PN03B - Axial Primary Node Operation % | BF47: PN03B - Axial Primary Node Instrument Retention | BG47: =P47 -> 0 | BH47: =AC47 -> 0 | BI47: =AP47 -> 0 | BJ47: =BD47 -> 0
C48: PN03B - Axial Primary Node Operational Days | D48: =IF(D47>=0.7,D$4,0) -> 0 | E48: =IF(E47>=0.7,E$4,0) -> 0 | F48: =IF(F47>=0.7,F$4,0) -> 0 | G48: =IF(G47>=0.7,G$4,0) -> 0 | H48: =IF(H47>=0.7,H$4,0) -> 0 | I48: =IF(I47>=0.7,I$4,0) -> 0 | J48: =IF(J47>=0.7,J$4,0) -> 0 | K48: =IF(K47>=0.7,K$4,0) -> 0 | ... BD48: =IF(BD47>=0.7,BD$4,0) -> 0 | BF48: PN03B - Axial Primary Node Platform Uptime | BG48: =IF(BG47="NA","NA",SUM(D48:P48)/SUM($D$4:$P$4)) -> 0 | BH48: =IF(BH47="NA","NA",SUM(R48:AC48)/SUM($R$4:$AC$4)) -> 0 | BI48: =IF(BI47="NA","NA",SUM(AD48:AP48)/SUM($AD$4:$AP$4)) -> 0 | BJ48: =IF(BJ47="NA","NA",SUM(AQ48:BD48)/SUM($AQ$4:$BD$4)) -> 0
C50: PN01B - Hydrate Ridge Primary Node Operation % | BF50: PN01B - Hydrate Ridge Primary Node Instrument Retention | BG50: =P50 -> 0 | BH50: =AC50 -> 0 | BI50: =AP50 -> 0 | BJ50: =BD50 -> 0
C51: PN01B - Hydrate Ridge Primary Node Operational Days | D51: =IF(D50>=0.7,D$4,0) -> 0 | E51: =IF(E50>=0.7,E$4,0) -> 0 | F51: =IF(F50>=0.7,F$4,0) -> 0 | G51: =IF(G50>=0.7,G$4,0) -> 0 | H51: =IF(H50>=0.7,H$4,0) -> 0 | I51: =IF(I50>=0.7,I$4,0) -> 0 | J51: =IF(J50>=0.7,J$4,0) -> 0 | K51: =IF(K50>=0.7,K$4,0) -> 0 | ... BD51: =IF(BD50>=0.7,BD$4,0) -> 0 | BF51: PN01B - Hydrate Ridge Primary Node Platform Uptime | BG51: =IF(BG50="NA","NA",SUM(D51:P51)/SUM($D$4:$P$4)) -> 0 | BH51: =IF(BH50="NA","NA",SUM(R51:AC51)/SUM($R$4:$AC$4)) -> 0 | BI51: =IF(BI50="NA","NA",SUM(AD51:AP51)/SUM($AD$4:$AP$4)) -> 0 | BJ51: =IF(BJ50="NA","NA",SUM(AQ51:BD51)/SUM($AQ$4:$BD$4)) -> 0
C53: Shore Station & Backhaul Operations % | BF53: Shore Station & Backhaul Instrument Retention | BG53: =P53 -> 0 | BH53: =AC53 -> 0 | BI53: =AP53 -> 0 | BJ53: =BD53 -> 0
C54: Shore Station & Backhaul Operational Days | D54: =IF(D53>=0.7,D$4,0) -> 0 | E54: =IF(E53>=0.7,E$4,0) -> 0 | F54: =IF(F53>=0.7,F$4,0) -> 0 | G54: =IF(G53>=0.7,G$4,0) -> 0 | H54: =IF(H53>=0.7,H$4,0) -> 0 | I54: =IF(I53>=0.7,I$4,0) -> 0 | J54: =IF(J53>=0.7,J$4,0) -> 0 | K54: =IF(K53>=0.7,K$4,0) -> 0 | ... BD54: =IF(BD53>=0.7,BD$4,0) -> 0 | BF54: Shore Station & Backhaul Platform Uptime | BG54: =IF(BG53="NA","NA",SUM(D54:P54)/SUM($D$4:$P$4)) -> 0 | BH54: =IF(BH53="NA","NA",SUM(R54:AC54)/SUM($R$4:$AC$4)) -> 0 | BI54: =IF(BI53="NA","NA",SUM(AD54:AP54)/SUM($AD$4:$AP$4)) -> 0 | BJ54: =IF(BJ53="NA","NA",SUM(AQ54:BD54)/SUM($AQ$4:$BD$4)) -> 0

Sheet Data Delivery
A1: Operations
A3: Start | B3: 45931 | C3: Week of | D3: 45936 | E3: =D3+7 -> 45943 | F3: =E3+7 -> 45950 | G3: =F3+7 -> 45957 | H3: =G3+7 -> 45964 | I3: =H3+7 -> 45971 | J3: =I3+7 -> 45978 | K3: =J3+7 -> 45985 | L3: =K3+7 -> 45992 | ... BC3: =BB3+7 -> 46293 | BD3: 46295 | BF3: Week of | BG3: 45936 | BH3: =BG3+7 -> 45943 | BI3: =BH3+7 -> 45950 | BJ3: =BI3+7 -> 45957 | BK3: =BJ3+7 -> 45964 | BL3: =BK3+7 -> 45971 | BM3: =BL3+7 -> 45978 | BN3: =BM3+7 -> 45985 | BO3: =BN3+7 -> 45992 | ... DF3: =DE3+7 -> 46293 | DG3: 46295 | DJ3: Q1 | DK3: Q2 | DL3: Q3 | DM3: Q4
BG4: 6 | BH4: 13 | BI4: 20 | BJ4: 27 | BK4: 34 | BL4: 41 | BM4: 48 | BN4: 55 | BO4: 62 | BP4: 69 | BQ4: 76 | BR4: 83 | BS4: 90 | BT4: 97 | BU4: 104 | BV4: 111 | BW4: 118 | BX4: 125 | BY4: 132 | BZ4: 139 | CA4: 146 | CB4: 153 | CC4: 160 | CD4: 167 | CE4: 174 | CF4: 181 | CG4: 188 | CH4: 195 | CI4: 202 | CJ4: 209 | CK4: 216 | CL4: 223 | CM4: 230 | CN4: 237 | CO4: 244 | CP4: 251 | CQ4: 258 | CR4: 265 | CS4: 272 | CT4: 279 | CU4: 286 | CV4: 293 | CW4: 300 | CX4: 307 | CY4: 314 | CZ4: 321 | DA4: 328 | DB4: 335 | DC4: 342 | DD4: 349 | DE4: 356 | DF4: 363 | DG4: 365
B7: Array | C7: Data Measure | BF7: Data Measure
B9: Pioneer
C10: CNSM Instruments Deployed | D10: 31 | E10: 31 | F10: 31 | G10: 31 | H10: 31 | I10: 31 | J10: 31 | K10: 31 | L10: 31 | M10: 31 | N10: 31 | O10: 31 | P10: 31 | Q10: 31 | R10: 31 | S10: 31 | T10: 31 | U10: 31 | V10: 31 | W10: 31 | X10: 31 | Y10: 31 | Z10: 31 | AA10: 31 | AB10: 31 | AC10: 31 | AD10: 31 | AE10: 31 | AF10: 31 | AG10: 31 | AH10: 31 | AI10: 31 | AJ10: 31 | AK10: 31 | AL10: 31 | AM10: 31 | AN10: 31 | AO10: 31 | AP10: 31
C11: CNSM Instruments Telemetering | D11: 28 | E11: 27 | F11: 27 | G11: 27 | H11: 27 | I11: 31 | J11: 31 | K11: 31 | L11: 31 | M11: 31 | N11: 29 | O11: 29 | P11: 28 | Q11: 28 | R11: 28 | S11: 28 | T11: 27 | U11: 27 | V11: 27 | W11: 27 | X11: 27 | Y11: 24 | Z11: 24 | AA11: 24 | AB11: 24 | AC11: 24 | AD11: 24 | AE11: 24 | AF11: 24 | AG11: 24 | AH11: 30 | AI11: 30 | AJ11: 29 | AK11: 29 | AL11: 29 | AM11: 29 | AN11: 29 | AO11: 29 | AP11: 29 | BF11: CNSM Technical Data Availability | BG11: =D11/(D10-D13) -> 1 | BH11: =E11/(E10-E13) -> 1 | BI11: =F11/(F10-F13) -> 1 | BJ11: =G11/(G10-G13) -> 1 | BK11: =H11/(H10-H13) -> 1 | BL11: =I11/(I10-I13) -> 1 | BM11: =J11/(J10-J13) -> 1 | BN11: =K11/(K10-K13) -> 1 | ... DG11: =BD11/(BD10-BD13) -> #DIV/0! | DI11: CNSM Technical Data Availability | DJ11: =AVERAGE(BG11:BS11) -> 1 | DK11: =AVERAGE(BT11:CF11) -> 1 | DL11: =AVERAGE(CG11:CS11) -> 1 | DM11: =AVERAGE(CT11:DG11) -> #DIV/0!
C12: CNSM Instruments Recovery Only | D12: 0 | E12: 0 | F12: 0 | G12: 0 | H12: 0 | I12: 0 | J12: 0 | K12: 0 | L12: 0 | M12: 0 | N12: 0 | O12: 0 | P12: 0 | Q12: 0 | R12: 0 | S12: 0 | T12: 0 | U12: 0 | V12: 0 | W12: 0 | X12: 0 | Y12: 5 | Z12: 5 | AA12: 5 | AB12: 5 | AC12: 5 | AD12: 5 | AE12: 5 | AF12: 5 | AG12: 5 | AH12: 0 | AI12: 0 | AJ12: 0 | AK12: 0 | AL12: 0 | AM12: 0 | AN12: 0 | AO12: 0 | AP12: 0 | BF12: CNSM Science Data Availability | BG12: =IF(D11=0,0,(D11-D12)/D11) -> 1 | BH12: =IF(E11=0,0,(E11-E12)/E11) -> 1 | BI12: =IF(F11=0,0,(F11-F12)/F11) -> 1 | BJ12: =IF(G11=0,0,(G11-G12)/G11) -> 1 | BK12: =IF(H11=0,0,(H11-H12)/H11) -> 1 | BL12: =IF(I11=0,0,(I11-I12)/I11) -> 1 | BM12: =IF(J11=0,0,(J11-J12)/J11) -> 1 | BN12: =IF(K11=0,0,(K11-K12)/K11) -> 1 | ... DG12: =IF(BD11=0,0,(BD11-BD12)/BD11) -> 0 | DI12: CNSM Science Data Availability | DJ12: =AVERAGE(BG12:BS12) -> 1 | DK12: =AVERAGE(BT12:CF12) -> 0.91987179 | DL12: =AVERAGE(CG12:CS12) -> 0.93589744 | DM12: =AVERAGE(CT12:DG12) -> 0
C13: CNSM Instruments Non-Recoverable | D13: 3 | E13: 4 | F13: 4 | G13: 4 | H13: 4 | I13: 0 | J13: 0 | K13: 0 | L13: 0 | M13: 0 | N13: 2 | O13: 2 | P13: 3 | Q13: 3 | R13: 3 | S13: 3 | T13: 4 | U13: 4 | V13: 4 | W13: 4 | X13: 4 | Y13: 7 | Z13: 7 | AA13: 7 | AB13: 7 | AC13: 7 | AD13: 7 | AE13: 7 | AF13: 7 | AG13: 7 | AH13: 1 | AI13: 1 | AJ13: 2 | AK13: 2 | AL13: 2 | AM13: 2 | AN13: 2 | AO13: 2 | AP13: 2 | BF13: CNSM Data Availability Retention | BG13: =(D10-D13)/D10 -> 0.90322581 | BH13: =(E10-E13)/E10 -> 0.87096774 | BI13: =(F10-F13)/F10 -> 0.87096774 | BJ13: =(G10-G13)/G10 -> 0.87096774 | BK13: =(H10-H13)/H10 -> 0.87096774 | BL13: =(I10-I13)/I10 -> 1 | BM13: =(J10-J13)/J10 -> 1 | BN13: =(K10-K13)/K10 -> 1 | ... DG13: =(BD10-BD13)/BD10 -> #DIV/0! | DI13: CNSM Data Availability Retention | DJ13: =AVERAGE(BG13:BS13) -> 0.93548387 | DK13: =AVERAGE(BT13:CF13) -> 0.84119107 | DL13: =AVERAGE(CG13:CS13) -> 0.89081886 | DM13: =AVERAGE(CT13:DG13) -> #DIV/0!
C15: CNSW Instruments Deployed | D15: 9 | E15: 9 | F15: 9 | G15: 9 | H15: 9 | I15: 9 | J15: 9 | K15: 9 | L15: 9 | M15: 9 | N15: 9 | O15: 9 | P15: 9 | Q15: 9 | R15: 9 | S15: 9 | T15: 9 | U15: 9 | V15: 9 | W15: 9 | X15: 9 | Y15: 9 | Z15: 9 | AA15: 9 | AB15: 9 | AC15: 9 | AD15: 9 | AE15: 9 | AF15: 9 | AG15: 9 | AH15: 9 | AI15: 9 | AJ15: 9 | AK15: 9 | AL15: 9 | AM15: 9 | AN15: 9 | AO15: 9 | AP15: 9
C16: CNSW Instruments Telemetering | D16: 9 | E16: 9 | F16: 9 | G16: 9 | H16: 9 | I16: 9 | J16: 9 | K16: 9 | L16: 9 | M16: 9 | N16: 9 | O16: 6 | P16: 6 | Q16: 6 | R16: 6 | S16: 6 | T16: 6 | U16: 6 | V16: 6 | W16: 6 | X16: 6 | Y16: 6 | Z16: 6 | AA16: 6 | AB16: 6 | AC16: 6 | AD16: 6 | AE16: 6 | AF16: 6 | AG16: 6 | AH16: 9 | AI16: 9 | AJ16: 9 | AK16: 9 | AL16: 9 | AM16: 9 | AN16: 9 | AO16: 9 | AP16: 9 | BF16: CNSW Technical Data Availability | BG16: =D16/(D15-D18) -> 1 | BH16: =E16/(E15-E18) -> 1 | BI16: =F16/(F15-F18) -> 1 | BJ16: =G16/(G15-G18) -> 1 | BK16: =H16/(H15-H18) -> 1 | BL16: =I16/(I15-I18) -> 1 | BM16: =J16/(J15-J18) -> 1 | BN16: =K16/(K15-K18) -> 1 | ... DG16: =BD16/(BD15-BD18) -> #DIV/0! | DI16: CNSW Technical Data Availability | DJ16: =AVERAGE(BG16:BS16) -> 0.94871795 | DK16: =AVERAGE(BT16:CF16) -> 0.66666667 | DL16: =AVERAGE(CG16:CS16) -> 0.8974359 | DM16: =AVERAGE(CT16:DG16) -> #DIV/0!
C17: CNSW Instruments Recovery Only | D17: 0 | E17: 0 | F17: 0 | G17: 0 | H17: 0 | I17: 0 | J17: 0 | K17: 0 | L17: 0 | M17: 0 | N17: 0 | O17: 3 | P17: 3 | Q17: 3 | R17: 3 | S17: 3 | T17: 3 | U17: 3 | V17: 3 | W17: 3 | X17: 3 | Y17: 3 | Z17: 3 | AA17: 3 | AB17: 3 | AC17: 3 | AD17: 3 | AE17: 3 | AF17: 3 | AG17: 3 | AH17: 0 | AI17: 0 | AJ17: 0 | AK17: 0 | AL17: 0 | AM17: 0 | AN17: 0 | AO17: 0 | AP17: 0 | BF17: CNSW Science Data Availability | BG17: =IF(D16=0,0,(D16-D17)/D16) -> 1 | BH17: =IF(E16=0,0,(E16-E17)/E16) -> 1 | BI17: =IF(F16=0,0,(F16-F17)/F16) -> 1 | BJ17: =IF(G16=0,0,(G16-G17)/G16) -> 1 | BK17: =IF(H16=0,0,(H16-H17)/H16) -> 1 | BL17: =IF(I16=0,0,(I16-I17)/I16) -> 1 | BM17: =IF(J16=0,0,(J16-J17)/J16) -> 1 | BN17: =IF(K16=0,0,(K16-K17)/K16) -> 1 | ... DG17: =IF(BD16=0,0,(BD16-BD17)/BD16) -> 0 | DI17: CNSW Science Data Availability | DJ17: =AVERAGE(BG17:BS17) -> 0.92307692 | DK17: =AVERAGE(BT17:CF17) -> 0.5 | DL17: =AVERAGE(CG17:CS17) -> 0.84615385 | DM17: =AVERAGE(CT17:DG17) -> 0
C18: CNSW Instruments Non-Recoverable | D18: 0 | E18: 0 | F18: 0 | G18: 0 | H18: 0 | I18: 0 | J18: 0 | K18: 0 | L18: 0 | M18: 0 | N18: 0 | O18: 0 | P18: 0 | Q18: 0 | R18: 0 | S18: 0 | T18: 0 | U18: 0 | V18: 0 | W18: 0 | X18: 0 | Y18: 0 | Z18: 0 | AA18: 0 | AB18: 0 | AC18: 0 | AD18: 0 | AE18: 0 | AF18: 0 | AG18: 0 | AH18: 0 | AI18: 0 | AJ18: 0 | AK18: 0 | AL18: 0 | AM18: 0 | AN18: 0 | AO18: 0 | AP18: 0 | BF18: CNSW Data Availability Retention | BG18: =(D15-D18)/D15 -> 1 | BH18: =(E15-E18)/E15 -> 1 | BI18: =(F15-F18)/F15 -> 1 | BJ18: =(G15-G18)/G15 -> 1 | BK18: =(H15-H18)/H15 -> 1 | BL18: =(I15-I18)/I15 -> 1 | BM18: =(J15-J18)/J15 -> 1 | BN18: =(K15-K18)/K15 -> 1 | ... DG18: =(BD15-BD18)/BD15 -> #DIV/0! | DI18: CNSW Data Availability Retention | DJ18: =AVERAGE(BG18:BS18) -> 1 | DK18: =AVERAGE(BT18:CF18) -> 1 | DL18: =AVERAGE(CG18:CS18) -> 1 | DM18: =AVERAGE(CT18:DG18) -> #DIV/0!
C20: NOPM Instruments Deployed | D20: 9 | E20: 9 | F20: 9 | G20: 9 | H20: 9 | I20: 9 | J20: 9 | K20: 9 | L20: 9 | M20: 9 | N20: 9 | O20: 9 | P20: 9 | Q20: 9 | R20: 9 | S20: 9 | T20: 9 | U20: 9 | V20: 9 | W20: 9 | X20: 9 | Y20: 9 | Z20: 9 | AA20: 9 | AB20: 9 | AC20: 9 | AD20: 9 | AE20: 9 | AF20: 9 | AG20: 9 | AH20: 9 | AI20: 9 | AJ20: 9 | AK20: 9 | AL20: 9 | AM20: 9 | AN20: 9 | AO20: 9 | AP20: 9
C21: NOPM Instruments Telemetering | D21: 8 | E21: 8 | F21: 8 | G21: 8 | H21: 8 | I21: 9 | J21: 0 | K21: 0 | L21: 0 | M21: 0 | N21: 0 | O21: 0 | P21: 0 | Q21: 0 | R21: 0 | S21: 0 | T21: 0 | U21: 0 | V21: 0 | W21: 0 | X21: 0 | Y21: 0 | Z21: 0 | AA21: 0 | AB21: 0 | AC21: 0 | AD21: 0 | AE21: 0 | AF21: 0 | AG21: 0 | AH21: 9 | AI21: 9 | AJ21: 9 | AK21: 9 | AL21: 9 | AM21: 9 | AN21: 9 | AO21: 9 | AP21: 9 | BF21: NOPM Technical Data Availability | BG21: =D21/(D20-D23) -> 1 | BH21: =E21/(E20-E23) -> 1 | BI21: =F21/(F20-F23) -> 1 | BJ21: =G21/(G20-G23) -> 1 | BK21: =H21/(H20-H23) -> 1 | BL21: =I21/(I20-I23) -> 1 | BM21: =J21/(J20-J23) -> 0 | BN21: =K21/(K20-K23) -> 0 | ... DG21: =BD21/(BD20-BD23) -> #DIV/0! | DI21: NOPM Technical Data Availability | DJ21: =AVERAGE(BG21:BS21) -> 0.46153846 | DK21: =AVERAGE(BT21:CF21) -> 0 | DL21: =AVERAGE(CG21:CS21) -> 0.69230769 | DM21: =AVERAGE(CT21:DG21) -> #DIV/0!
C22: NOPM Instruments Recovery Only | D22: 0 | E22: 0 | F22: 0 | G22: 0 | H22: 0 | I22: 0 | J22: 9 | K22: 9 | L22: 9 | M22: 9 | N22: 9 | O22: 9 | P22: 9 | Q22: 9 | R22: 9 | S22: 9 | T22: 9 | U22: 9 | V22: 9 | W22: 9 | X22: 9 | Y22: 9 | Z22: 9 | AA22: 9 | AB22: 9 | AC22: 9 | AD22: 9 | AE22: 9 | AF22: 9 | AG22: 9 | AH22: 0 | AI22: 0 | AJ22: 0 | AK22: 0 | AL22: 0 | AM22: 0 | AN22: 0 | AO22: 0 | AP22: 0 | BF22: NOPM Science Data Availability | BG22: =IF(D21=0,0,(D21-D22)/D21) -> 1 | BH22: =IF(E21=0,0,(E21-E22)/E21) -> 1 | BI22: =IF(F21=0,0,(F21-F22)/F21) -> 1 | BJ22: =IF(G21=0,0,(G21-G22)/G21) -> 1 | BK22: =IF(H21=0,0,(H21-H22)/H21) -> 1 | BL22: =IF(I21=0,0,(I21-I22)/I21) -> 1 | BM22: =IF(J21=0,0,(J21-J22)/J21) -> 0 | BN22: =IF(K21=0,0,(K21-K22)/K21) -> 0 | ... DG22: =IF(BD21=0,0,(BD21-BD22)/BD21) -> 0 | DI22: NOPM Science Data Availability | DJ22: =AVERAGE(BG22:BS22) -> 0.46153846 | DK22: =AVERAGE(BT22:CF22) -> 0 | DL22: =AVERAGE(CG22:CS22) -> 0.69230769 | DM22: =AVERAGE(CT22:DG22) -> 0
C23: NOPM Instruments Non-Recoverable | D23: 1 | E23: 1 | F23: 1 | G23: 1 | H23: 1 | I23: 0 | J23: 0 | K23: 0 | L23: 0 | M23: 0 | N23: 0 | O23: 0 | P23: 0 | Q23: 0 | R23: 0 | S23: 0 | T23: 0 | U23: 0 | V23: 0 | W23: 0 | X23: 0 | Y23: 0 | Z23: 0 | AA23: 0 | AB23: 0 | AC23: 0 | AD23: 0 | AE23: 0 | AF23: 0 | AG23: 0 | AH23: 0 | AI23: 0 | AJ23: 0 | AK23: 0 | AL23: 0 | AM23: 0 | AN23: 0 | AO23: 0 | AP23: 0 | BF23: NOPM Data Availability Retention | BG23: =(D20-D23)/D20 -> 0.88888889 | BH23: =(E20-E23)/E20 -> 0.88888889 | BI23: =(F20-F23)/F20 -> 0.88888889 | BJ23: =(G20-G23)/G20 -> 0.88888889 | BK23: =(H20-H23)/H20 -> 0.88888889 | BL23: =(I20-I23)/I20 -> 1 | BM23: =(J20-J23)/J20 -> 1 | BN23: =(K20-K23)/K20 -> 1 | ... DG23: =(BD20-BD23)/BD20 -> #DIV/0! | DI23: NOPM Data Availability Retention | DJ23: =AVERAGE(BG23:BS23) -> 0.95726496 | DK23: =AVERAGE(BT23:CF23) -> 1 | DL23: =AVERAGE(CG23:CS23) -> 1 | DM23: =AVERAGE(CT23:DG23) -> #DIV/0!
C25: SOPM Instruments Deployed | D25: 9 | E25: 9 | F25: 9 | G25: 9 | H25: 9 | I25: 9 | J25: 9 | K25: 9 | L25: 9 | M25: 9 | N25: 9 | O25: 9 | P25: 9 | Q25: 9 | R25: 9 | S25: 9 | T25: 9 | U25: 9 | V25: 9 | W25: 9 | X25: 9 | Y25: 9 | Z25: 9 | AA25: 9 | AB25: 9 | AC25: 9 | AD25: 9 | AE25: 9 | AF25: 9 | AG25: 9 | AH25: 9 | AI25: 9 | AJ25: 9 | AK25: 9 | AL25: 9 | AM25: 9 | AN25: 9 | AO25: 9 | AP25: 9
C26: SOPM Instruments Telemetering | D26: 9 | E26: 9 | F26: 9 | G26: 9 | H26: 9 | I26: 9 | J26: 9 | K26: 9 | L26: 9 | M26: 9 | N26: 9 | O26: 9 | P26: 9 | Q26: 9 | R26: 9 | S26: 9 | T26: 9 | U26: 9 | V26: 9 | W26: 9 | X26: 9 | Y26: 9 | Z26: 9 | AA26: 9 | AB26: 9 | AC26: 9 | AD26: 9 | AE26: 9 | AF26: 9 | AG26: 9 | AH26: 9 | AI26: 9 | AJ26: 9 | AK26: 9 | AL26: 9 | AM26: 9 | AN26: 9 | AO26: 9 | AP26: 9 | BF26: SOPM Technical Data Availability | BG26: =D26/(D25-D28) -> 1 | BH26: =E26/(E25-E28) -> 1 | BI26: =F26/(F25-F28) -> 1 | BJ26: =G26/(G25-G28) -> 1 | BK26: =H26/(H25-H28) -> 1 | BL26: =I26/(I25-I28) -> 1 | BM26: =J26/(J25-J28) -> 1 | BN26: =K26/(K25-K28) -> 1 | ... DG26: =BD26/(BD25-BD28) -> #DIV/0! | DI26: SOPM Technical Data Availability | DJ26: =AVERAGE(BG26:BS26) -> 1 | DK26: =AVERAGE(BT26:CF26) -> 1 | DL26: =AVERAGE(CG26:CS26) -> 1 | DM26: =AVERAGE(CT26:DG26) -> #DIV/0!
C27: SOPM Instruments Recovery Only | D27: 0 | E27: 0 | F27: 0 | G27: 0 | H27: 0 | I27: 0 | J27: 0 | K27: 0 | L27: 0 | M27: 0 | N27: 0 | O27: 0 | P27: 0 | Q27: 0 | R27: 0 | S27: 0 | T27: 0 | U27: 0 | V27: 0 | W27: 0 | X27: 0 | Y27: 0 | Z27: 0 | AA27: 0 | AB27: 0 | AC27: 0 | AD27: 0 | AE27: 0 | AF27: 0 | AG27: 0 | AH27: 0 | AI27: 0 | AJ27: 0 | AK27: 0 | AL27: 0 | AM27: 0 | AN27: 0 | AO27: 0 | AP27: 0 | BF27: SOPM Science Data Availability | BG27: =IF(D26=0,0,(D26-D27)/D26) -> 1 | BH27: =IF(E26=0,0,(E26-E27)/E26) -> 1 | BI27: =IF(F26=0,0,(F26-F27)/F26) -> 1 | BJ27: =IF(G26=0,0,(G26-G27)/G26) -> 1 | BK27: =IF(H26=0,0,(H26-H27)/H26) -> 1 | BL27: =IF(I26=0,0,(I26-I27)/I26) -> 1 | BM27: =IF(J26=0,0,(J26-J27)/J26) -> 1 | BN27: =IF(K26=0,0,(K26-K27)/K26) -> 1 | ... DG27: =IF(BD26=0,0,(BD26-BD27)/BD26) -> 0 | DI27: SOPM Science Data Availability | DJ27: =AVERAGE(BG27:BS27) -> 1 | DK27: =AVERAGE(BT27:CF27) -> 1 | DL27: =AVERAGE(CG27:CS27) -> 1 | DM27: =AVERAGE(CT27:DG27) -> 0
C28: SOPM Instruments Non-Recoverable | D28: 0 | E28: 0 | F28: 0 | G28: 0 | H28: 0 | I28: 0 | J28: 0 | K28: 0 | L28: 0 | M28: 0 | N28: 0 | O28: 0 | P28: 0 | Q28: 0 | R28: 0 | S28: 0 | T28: 0 | U28: 0 | V28: 0 | W28: 0 | X28: 0 | Y28: 0 | Z28: 0 | AA28: 0 | AB28: 0 | AC28: 0 | AD28: 0 | AE28: 0 | AF28: 0 | AG28: 0 | AH28: 0 | AI28: 0 | AJ28: 0 | AK28: 0 | AL28: 0 | AM28: 0 | AN28: 0 | AO28: 0 | AP28: 0 | BF28: SOPM Data Availability Retention | BG28: =(D25-D28)/D25 -> 1 | BH28: =(E25-E28)/E25 -> 1 | BI28: =(F25-F28)/F25 -> 1 | BJ28: =(G25-G28)/G25 -> 1 | BK28: =(H25-H28)/H25 -> 1 | BL28: =(I25-I28)/I25 -> 1 | BM28: =(J25-J28)/J25 -> 1 | BN28: =(K25-K28)/K25 -> 1 | ... DG28: =(BD25-BD28)/BD25 -> #DIV/0! | DI28: SOPM Data Availability Retention | DJ28: =AVERAGE(BG28:BS28) -> 1 | DK28: =AVERAGE(BT28:CF28) -> 1 | DL28: =AVERAGE(CG28:CS28) -> 1 | DM28: =AVERAGE(CT28:DG28) -> #DIV/0!
B31: Regional Cabled Array
C32: RCA Technical Data Availability | D32: 0.97 | E32: 0.98 | F32: 0.94 | G32: 0.98 | H32: 0.98 | I32: 0.96 | J32: 0.97 | K32: 0.96 | L32: 0.96 | M32: 0.96 | N32: 0.96 | O32: 0.96 | P32: 0.97 | Q32: 0.97 | R32: 0.97 | S32: 0.98 | T32: 0.98 | U32: 0.97 | V32: 0.98 | W32: 0.98 | X32: 0.98 | Y32: 0.98 | Z32: 0.98 | AA32: 0.98 | AB32: 0.98 | AC32: 0.98 | AD32: 0.98 | AE32: 0.98 | AF32: 0.98 | AG32: 0.98 | AH32: 0.98 | AI32: 0.98 | AJ32: 0.98 | AK32: 0.98 | AL32: 0.98 | AM32: 0.98 | AN32: 0.98 | AO32: 0.98 | AP32: 0.98 | BF32: RCA Technical Data Availability | BG32: =D32 -> 0.97 | BH32: =E32 -> 0.98 | BI32: =F32 -> 0.94 | BJ32: =G32 -> 0.98 | BK32: =H32 -> 0.98 | BL32: =I32 -> 0.96 | BM32: =J32 -> 0.97 | BN32: =K32 -> 0.96 | ... DG32: =BD32 -> 0 | DI32: RCA Technical Data Availability | DJ32: =AVERAGE(BG32:BS32) -> 0.96538462 | DK32: =AVERAGE(BT32:CF32) -> 0.97769231 | DL32: =AVERAGE(CG32:CS32) -> 0.98 | DM32: =AVERAGE(CT32:DG32) -> 0
C33: RCA Science Data Availability | D33: 0.96 | E33: 0.96 | F33: 0.96 | G33: 0.96 | H33: 0.96 | I33: 0.96 | J33: 0.96 | K33: 0.96 | L33: 0.96 | M33: 0.96 | N33: 0.96 | O33: 0.96 | P33: 0.96 | Q33: 0.96 | R33: 0.97 | S33: 0.96 | T33: 0.97 | U33: 0.97 | V33: 0.97 | W33: 0.97 | X33: 0.97 | Y33: 0.97 | Z33: 0.97 | AA33: 0.97 | AB33: 0.96 | AC33: 0.95 | AD33: 0.95 | AE33: 0.95 | AF33: 0.95 | AG33: 0.95 | AH33: 0.95 | AI33: 0.94 | AJ33: 0.94 | AK33: 0.93 | AL33: 0.94 | AM33: 0.93 | AN33: 0.94 | AO33: 0.94 | AP33: 0.94 | BF33: RCA Science Data Availability | BG33: =D33 -> 0.96 | BH33: =E33 -> 0.96 | BI33: =F33 -> 0.96 | BJ33: =G33 -> 0.96 | BK33: =H33 -> 0.96 | BL33: =I33 -> 0.96 | BM33: =J33 -> 0.96 | BN33: =K33 -> 0.96 | ... DG33: =BD33 -> 0 | DI33: RCA Science Data Availability | DJ33: =AVERAGE(BG33:BS33) -> 0.96 | DK33: =AVERAGE(BT33:CF33) -> 0.96615385 | DL33: =AVERAGE(CG33:CS33) -> 0.94230769 | DM33: =AVERAGE(CT33:DG33) -> 0
C34: RCA Data Availability Retention | D34: 0.94 | E34: 0.96 | F34: 0.91 | G34: 0.94 | H34: 0.93 | I34: 0.92 | J34: 0.92 | K34: 0.91 | L34: 0.91 | M34: 0.91 | N34: 0.9 | O34: 0.91 | P34: 0.91 | Q34: 0.91 | R34: 0.91 | S34: 0.92 | T34: 0.92 | U34: 0.91 | V34: 0.92 | W34: 0.92 | X34: 0.91 | Y34: 0.91 | Z34: 0.91 | AA34: 0.91 | AB34: 0.92 | AC34: 0.91 | AD34: 0.92 | AE34: 0.92 | AF34: 0.91 | AG34: 0.91 | AH34: 0.91 | AI34: 0.91 | AJ34: 0.91 | AK34: 0.91 | AL34: 0.91 | AM34: 0.91 | AN34: 0.91 | AO34: 0.91 | AP34: 0.91 | BF34: RCA Data Availability Retention | BG34: =D34 -> 0.94 | BH34: =E34 -> 0.96 | BI34: =F34 -> 0.91 | BJ34: =G34 -> 0.94 | BK34: =H34 -> 0.93 | BL34: =I34 -> 0.92 | BM34: =J34 -> 0.92 | BN34: =K34 -> 0.91 | ... DG34: =BD34 -> 0 | DI34: RCA Data Availability Retention | DJ34: =AVERAGE(BG34:BS34) -> 0.92076923 | DK34: =AVERAGE(BT34:CF34) -> 0.91384615 | DL34: =AVERAGE(CG34:CS34) -> 0.91153846 | DM34: =AVERAGE(CT34:DG34) -> 0
